[I 220303 10:26:54 interface:134] b'\r\nAnalysis Almost Complete:\r\n\r\nAnalysis Results:\r\n\r\nPerson Group Created For User\r\n\r\n'
[I 220303 10:26:54 interface:139] b'Traceback (most recent call last):\r\n  File "C:\\Users\\Ceere\\Documents\\Hackathon\\projectcode\\facerecognition.py", line 173, in <module>\r\n    analysis()\r\n  File "C:\\Users\\Ceere\\Documents\\Hackathon\\projectcode\\facerecognition.py", line 171, in analysis\r\n    keys()\r\n  File "C:\\Users\\Ceere\\Documents\\Hackathon\\projectcode\\facerecognition.py", line 54, in keys\r\n    face_client.person_group.create(person_group_id=PERSON_GROUP_ID, name=PERSON_GROUP_ID)\r\n  File "C:\\Users\\Ceere\\AppData\\Local\\Programs\\Python\\Python39\\lib\\site-packages\\azure\\cognitiveservices\\vision\\face\\operations\\_person_group_operations.py", line 117, in create\r\n    request = self._client.put(url, query_parameters, header_parameters, body_content)\r\n  File "C:\\Users\\Ceere\\AppData\\Local\\Programs\\Python\\Python39\\lib\\site-packages\\msrest\\service_client.py", line 181, in put\r\n    request = self._request(\'PUT\', url, params, headers, content, form_content)\r\n  File "C:\\Users\\Ceere\\AppData\\Local\\Programs\\Python\\Python39\\lib\\site-packages\\msrest\\service_client.py", line 108, in _request\r\n    request = ClientRequest(method, self.format_url(url))\r\n  File "C:\\Users\\Ceere\\AppData\\Local\\Programs\\Python\\Python39\\lib\\site-packages\\msrest\\service_client.py", line 155, in format_url\r\n    base = self.config.base_url.format(**kwargs).rstrip(\'/\')\r\nKeyError: \'Endpoint\'\r\n'
[I 220308 13:25:17 interface:134] b'\r\nAnalysis Almost Complete:\r\n\r\nAnalysis Results:\r\n\r\nPerson Group Created For User\r\n\r\n'
[I 220308 13:25:17 interface:139] b'Traceback (most recent call last):\r\n  File "C:\\Users\\Ceere\\Documents\\Hackathon\\projectcode\\facerecognition.py", line 173, in <module>\r\n    analysis()\r\n  File "C:\\Users\\Ceere\\Documents\\Hackathon\\projectcode\\facerecognition.py", line 171, in analysis\r\n    keys()\r\n  File "C:\\Users\\Ceere\\Documents\\Hackathon\\projectcode\\facerecognition.py", line 54, in keys\r\n    face_client.person_group.create(person_group_id=PERSON_GROUP_ID, name=PERSON_GROUP_ID)\r\n  File "C:\\Users\\Ceere\\AppData\\Local\\Programs\\Python\\Python39\\lib\\site-packages\\azure\\cognitiveservices\\vision\\face\\operations\\_person_group_operations.py", line 117, in create\r\n    request = self._client.put(url, query_parameters, header_parameters, body_content)\r\n  File "C:\\Users\\Ceere\\AppData\\Local\\Programs\\Python\\Python39\\lib\\site-packages\\msrest\\service_client.py", line 181, in put\r\n    request = self._request(\'PUT\', url, params, headers, content, form_content)\r\n  File "C:\\Users\\Ceere\\AppData\\Local\\Programs\\Python\\Python39\\lib\\site-packages\\msrest\\service_client.py", line 108, in _request\r\n    request = ClientRequest(method, self.format_url(url))\r\n  File "C:\\Users\\Ceere\\AppData\\Local\\Programs\\Python\\Python39\\lib\\site-packages\\msrest\\service_client.py", line 155, in format_url\r\n    base = self.config.base_url.format(**kwargs).rstrip(\'/\')\r\nKeyError: \'Endpoint\'\r\n'
[I 220308 13:30:18 interface:134] b'\r\nAnalysis Almost Complete:\r\n\r\nAnalysis Results:\r\n\r\nPerson Group Created For User\r\n\r\n'
[I 220308 13:30:18 interface:139] b'Traceback (most recent call last):\r\n  File "C:\\Users\\Ceere\\Documents\\Hackathon\\projectcode\\facerecognition.py", line 173, in <module>\r\n    analysis()\r\n  File "C:\\Users\\Ceere\\Documents\\Hackathon\\projectcode\\facerecognition.py", line 171, in analysis\r\n    keys()\r\n  File "C:\\Users\\Ceere\\Documents\\Hackathon\\projectcode\\facerecognition.py", line 54, in keys\r\n    face_client.person_group.create(person_group_id=PERSON_GROUP_ID, name=PERSON_GROUP_ID)\r\n  File "C:\\Users\\Ceere\\AppData\\Local\\Programs\\Python\\Python39\\lib\\site-packages\\azure\\cognitiveservices\\vision\\face\\operations\\_person_group_operations.py", line 117, in create\r\n    request = self._client.put(url, query_parameters, header_parameters, body_content)\r\n  File "C:\\Users\\Ceere\\AppData\\Local\\Programs\\Python\\Python39\\lib\\site-packages\\msrest\\service_client.py", line 181, in put\r\n    request = self._request(\'PUT\', url, params, headers, content, form_content)\r\n  File "C:\\Users\\Ceere\\AppData\\Local\\Programs\\Python\\Python39\\lib\\site-packages\\msrest\\service_client.py", line 108, in _request\r\n    request = ClientRequest(method, self.format_url(url))\r\n  File "C:\\Users\\Ceere\\AppData\\Local\\Programs\\Python\\Python39\\lib\\site-packages\\msrest\\service_client.py", line 155, in format_url\r\n    base = self.config.base_url.format(**kwargs).rstrip(\'/\')\r\nKeyError: \'Endpoint\'\r\n'
[I 220308 13:38:38 interface:134] b'\r\nAnalysis Almost Complete:\r\n\r\nAnalysis Results:\r\n\r\nPerson Group Created For User\r\n\r\n'
[I 220308 13:38:38 interface:139] b'Traceback (most recent call last):\r\n  File "C:\\Users\\Ceere\\Documents\\Hackathon\\projectcode\\facerecognition.py", line 173, in <module>\r\n    analysis()\r\n  File "C:\\Users\\Ceere\\Documents\\Hackathon\\projectcode\\facerecognition.py", line 171, in analysis\r\n    keys()\r\n  File "C:\\Users\\Ceere\\Documents\\Hackathon\\projectcode\\facerecognition.py", line 54, in keys\r\n    face_client.person_group.create(person_group_id=PERSON_GROUP_ID, name=PERSON_GROUP_ID)\r\n  File "C:\\Users\\Ceere\\AppData\\Local\\Programs\\Python\\Python39\\lib\\site-packages\\azure\\cognitiveservices\\vision\\face\\operations\\_person_group_operations.py", line 121, in create\r\n    raise models.APIErrorException(self._deserialize, response)\r\nazure.cognitiveservices.vision.face.models._models_py3.APIErrorException: (404) Resource not found\r\n'
[I 220308 13:52:57 interface:134] b'\r\nAnalysis Almost Complete:\r\n\r\nAnalysis Results:\r\n\r\nPerson Group Created For User\r\n\r\n'
[I 220308 13:52:57 interface:139] b'Traceback (most recent call last):\r\n  File "C:\\Users\\Ceere\\Documents\\Hackathon\\projectcode\\facerecognition.py", line 173, in <module>\r\n    analysis()\r\n  File "C:\\Users\\Ceere\\Documents\\Hackathon\\projectcode\\facerecognition.py", line 171, in analysis\r\n    keys()\r\n  File "C:\\Users\\Ceere\\Documents\\Hackathon\\projectcode\\facerecognition.py", line 54, in keys\r\n    face_client.person_group.create(person_group_id=PERSON_GROUP_ID, name=PERSON_GROUP_ID)\r\n  File "C:\\Users\\Ceere\\AppData\\Local\\Programs\\Python\\Python39\\lib\\site-packages\\azure\\cognitiveservices\\vision\\face\\operations\\_person_group_operations.py", line 121, in create\r\n    raise models.APIErrorException(self._deserialize, response)\r\nazure.cognitiveservices.vision.face.models._models_py3.APIErrorException: (404) Resource not found\r\n'
[I 220308 13:57:24 interface:139] b"'facerecognition2.py' is not recognized as an internal or external command,\r\noperable program or batch file.\r\n"
[I 220308 13:59:28 interface:139] b"'facerecognition.py' is not recognized as an internal or external command,\r\noperable program or batch file.\r\n"
[I 220308 14:04:02 interface:134] b'Person group: c4f29447-9c27-4254-9f16-974f46a09ccb\r\n'
[I 220308 14:04:02 interface:139] b'Traceback (most recent call last):\r\n  File "C:\\Users\\Ceere\\Documents\\Hackathon\\projectcode\\facerecognition.py", line 86, in <module>\r\n    randomlist_images = random.sample(range(0,i), 4)\r\n  File "C:\\Users\\Ceere\\AppData\\Local\\Programs\\Python\\Python39\\lib\\random.py", line 449, in sample\r\n    raise ValueError("Sample larger than population or is negative")\r\nValueError: Sample larger than population or is negative\r\n'
[I 220308 14:10:35 interface:134] b'Person group: ef7a2dbd-eaa5-4bc5-b9a6-231f5f9d55c6\r\n[13, 11, 6, 8]\r\n[13, 11, 6, 8]\r\n[13, 11, 6, 8]\r\n[13, 11, 6, 8]\r\n\r\nTraining the person group...\r\nTraining status: running.\r\n\r\nTraining status: succeeded.\r\n\r\nIdentifying faces in testimage.jpg\r\nPerson for face ID a9a6072b-5253-4e3f-8da4-572e556ad7ae is identified in testimage.jpg with a confidence of 0.54956.\r\nPerson group: ef7a2dbd-eaa5-4bc5-b9a6-231f5f9d55c6\r\n'
[I 220308 14:10:35 interface:139] b'Traceback (most recent call last):\r\n  File "C:\\Users\\Ceere\\Documents\\Hackathon\\projectcode\\facerecognition.py", line 212, in <module>\r\n    face_client.person_group.create(person_group_id=PERSON_GROUP_ID, name=PERSON_GROUP_ID)\r\n  File "C:\\Users\\Ceere\\AppData\\Local\\Programs\\Python\\Python39\\lib\\site-packages\\azure\\cognitiveservices\\vision\\face\\operations\\_person_group_operations.py", line 121, in create\r\n    raise models.APIErrorException(self._deserialize, response)\r\nazure.cognitiveservices.vision.face.models._models_py3.APIErrorException: (PersonGroupExists) Person group \'ef7a2dbd-eaa5-4bc5-b9a6-231f5f9d55c6\' already exists.\r\n'
[I 220308 14:17:18 interface:134] b'Person group: 5e925254-7a06-43a0-8515-f866b1b319ce\r\n[2, 4, 0, 11]\r\n[2, 4, 0, 11]\r\n[2, 4, 0, 11]\r\n[2, 4, 0, 11]\r\n\r\nTraining the person group...\r\nTraining status: running.\r\n\r\nTraining status: succeeded.\r\n\r\nIdentifying faces in testimage.jpg\r\nPerson for face ID fa72a473-3084-4604-8bde-1e8fe632bc63 is identified in testimage.jpg with a confidence of 0.56626.\r\nPerson group: 5e925254-7a06-43a0-8515-f866b1b319ce\r\n'
[I 220308 14:17:18 interface:139] b'Traceback (most recent call last):\r\n  File "C:\\Users\\Ceere\\Documents\\Hackathon\\projectcode\\facerecognition.py", line 212, in <module>\r\n    face_client.person_group.create(person_group_id=PERSON_GROUP_ID, name=PERSON_GROUP_ID)\r\n  File "C:\\Users\\Ceere\\AppData\\Local\\Programs\\Python\\Python39\\lib\\site-packages\\azure\\cognitiveservices\\vision\\face\\operations\\_person_group_operations.py", line 121, in create\r\n    raise models.APIErrorException(self._deserialize, response)\r\nazure.cognitiveservices.vision.face.models._models_py3.APIErrorException: (PersonGroupExists) Person group \'5e925254-7a06-43a0-8515-f866b1b319ce\' already exists.\r\n'
[I 220308 14:22:36 interface:134] b'Person group: 11558a9e-fbe2-4f19-ab5c-7773751a997e\r\n[8, 13, 5, 4]\r\n[8, 13, 5, 4]\r\n[8, 13, 5, 4]\r\n[8, 13, 5, 4]\r\n\r\nTraining the person group...\r\nTraining status: running.\r\n\r\nTraining status: succeeded.\r\n\r\n'
[I 220308 14:22:36 interface:139] b'Traceback (most recent call last):\r\n  File "C:\\Users\\Ceere\\Documents\\Hackathon\\projectcode\\facerecognition.py", line 160, in <module>\r\n    image = open(test_image_array[0], \'r+b\')\r\nIndexError: list index out of range\r\n'
[I 220308 14:33:56 interface2:134] b'Person group: 8d812365-2f86-426a-bf74-d9c959fb2f94\r\n[11, 14, 5, 6]\r\n[11, 14, 5, 6]\r\n'
[I 220308 14:33:56 interface2:139] b'Traceback (most recent call last):\r\n  File "C:\\Users\\Ceere\\Documents\\Hackathon\\projectcode\\facerecognition.py", line 129, in <module>\r\n    face_client.person_group_person.add_face_from_stream(PERSON_GROUP_ID, janetceere.person_id,k)\r\n  File "C:\\Users\\Ceere\\AppData\\Local\\Programs\\Python\\Python39\\lib\\site-packages\\azure\\cognitiveservices\\vision\\face\\operations\\_person_group_person_operations.py", line 767, in add_face_from_stream\r\n    raise models.APIErrorException(self._deserialize, response)\r\nazure.cognitiveservices.vision.face.models._models_py3.APIErrorException: (InvalidImage) No face detected in the image.\r\n'
[I 220308 14:36:41 interface2:134] b'Person group: 2afa9d97-c2ce-4dc1-b807-9f12d09f4a4f\r\n[10, 2, 4, 8]\r\n[10, 2, 4, 8]\r\n[10, 2, 4, 8]\r\n[10, 2, 4, 8]\r\n\r\nTraining the person group...\r\nTraining status: running.\r\n\r\nTraining status: succeeded.\r\n\r\n'
[I 220308 14:36:41 interface2:139] b'Traceback (most recent call last):\r\n  File "C:\\Users\\Ceere\\Documents\\Hackathon\\projectcode\\facerecognition.py", line 160, in <module>\r\n    image = open(test_image_array[0], \'r+b\')\r\nIndexError: list index out of range\r\n'
[I 220308 14:39:55 interface2:134] b'Person group: 607c7cd1-12e6-4c30-9f55-e40f10d660c1\r\n[9, 1, 0, 8]\r\n[9, 1, 0, 8]\r\n[9, 1, 0, 8]\r\n[9, 1, 0, 8]\r\n\r\nTraining the person group...\r\nTraining status: running.\r\n\r\nTraining status: succeeded.\r\n\r\nIdentifying faces in testimage.png\r\nPerson for face ID f128688d-81bb-448c-a59a-f69ec1543ab2 is identified in testimage.png with a confidence of 0.56151.\r\nPerson group: 607c7cd1-12e6-4c30-9f55-e40f10d660c1\r\n'
[I 220308 14:39:55 interface2:139] b'Traceback (most recent call last):\r\n  File "C:\\Users\\Ceere\\Documents\\Hackathon\\projectcode\\facerecognition.py", line 212, in <module>\r\n    face_client.person_group.create(person_group_id=PERSON_GROUP_ID, name=PERSON_GROUP_ID)\r\n  File "C:\\Users\\Ceere\\AppData\\Local\\Programs\\Python\\Python39\\lib\\site-packages\\azure\\cognitiveservices\\vision\\face\\operations\\_person_group_operations.py", line 121, in create\r\n    raise models.APIErrorException(self._deserialize, response)\r\nazure.cognitiveservices.vision.face.models._models_py3.APIErrorException: (PersonGroupExists) Person group \'607c7cd1-12e6-4c30-9f55-e40f10d660c1\' already exists.\r\n'
[I 220308 14:48:15 interface2:134] b'Person group: 0bd2ea7c-24ce-47d6-b4a2-27917c0900bc\r\n[5, 2, 12, 7]\r\n[5, 2, 12, 7]\r\n'
[I 220308 14:48:15 interface2:139] b'Traceback (most recent call last):\r\n  File "C:\\Users\\Ceere\\Documents\\Hackathon\\projectcode\\facerecognition.py", line 129, in <module>\r\n    face_client.person_group_person.add_face_from_stream(PERSON_GROUP_ID, janetceere.person_id,k)\r\n  File "C:\\Users\\Ceere\\AppData\\Local\\Programs\\Python\\Python39\\lib\\site-packages\\azure\\cognitiveservices\\vision\\face\\operations\\_person_group_person_operations.py", line 767, in add_face_from_stream\r\n    raise models.APIErrorException(self._deserialize, response)\r\nazure.cognitiveservices.vision.face.models._models_py3.APIErrorException: (InvalidImage) No face detected in the image.\r\n'
[I 220308 14:50:59 interface2:134] b'Person group: 319cea13-9881-42fb-ae30-87aea9c608e4\r\n[5, 7, 11, 3]\r\n[5, 7, 11, 3]\r\n[5, 7, 11, 3]\r\n[5, 7, 11, 3]\r\n\r\nTraining the person group...\r\nTraining status: succeeded.\r\n\r\nIdentifying faces in testimage.png\r\nUnidentified person for face ID b06bd3b4-4420-4e3a-8ace-fa5f7342789e in testimage.png.\r\nPerson group: 319cea13-9881-42fb-ae30-87aea9c608e4\r\n'
[I 220308 14:50:59 interface2:139] b'Traceback (most recent call last):\r\n  File "C:\\Users\\Ceere\\Documents\\Hackathon\\projectcode\\facerecognition.py", line 212, in <module>\r\n    face_client.person_group.create(person_group_id=PERSON_GROUP_ID, name=PERSON_GROUP_ID)\r\n  File "C:\\Users\\Ceere\\AppData\\Local\\Programs\\Python\\Python39\\lib\\site-packages\\azure\\cognitiveservices\\vision\\face\\operations\\_person_group_operations.py", line 121, in create\r\n    raise models.APIErrorException(self._deserialize, response)\r\nazure.cognitiveservices.vision.face.models._models_py3.APIErrorException: (PersonGroupExists) Person group \'319cea13-9881-42fb-ae30-87aea9c608e4\' already exists.\r\n'
[I 220308 14:56:08 interface2:134] b'Person group: a2224703-5b1a-42c2-a306-b32658614133\r\n[12, 8, 14, 2]\r\n[12, 8, 14, 2]\r\n[12, 8, 14, 2]\r\n'
[I 220308 14:56:08 interface2:139] b'Traceback (most recent call last):\r\n  File "C:\\Users\\Ceere\\Documents\\Hackathon\\projectcode\\facerecognition.py", line 129, in <module>\r\n    face_client.person_group_person.add_face_from_stream(PERSON_GROUP_ID, janetceere.person_id,k)\r\n  File "C:\\Users\\Ceere\\AppData\\Local\\Programs\\Python\\Python39\\lib\\site-packages\\azure\\cognitiveservices\\vision\\face\\operations\\_person_group_person_operations.py", line 767, in add_face_from_stream\r\n    raise models.APIErrorException(self._deserialize, response)\r\nazure.cognitiveservices.vision.face.models._models_py3.APIErrorException: (InvalidImage) No face detected in the image.\r\n'
[I 220308 15:04:36 interface2:134] b'Person group: a066b34f-2968-4f63-8fea-f5a3bc437a75\r\n[10, 11, 13, 6]\r\n[10, 11, 13, 6]\r\n[10, 11, 13, 6]\r\n[10, 11, 13, 6]\r\n\r\nTraining the person group...\r\nTraining status: running.\r\n\r\nTraining status: succeeded.\r\n\r\nIdentifying faces in testimage.png\r\nPerson for face ID 1bffba55-e186-4f85-b034-215da84d03aa is identified in testimage.png with a confidence of 0.75536.\r\nPerson group: a066b34f-2968-4f63-8fea-f5a3bc437a75\r\n'
[I 220308 15:04:36 interface2:139] b'Traceback (most recent call last):\r\n  File "C:\\Users\\Ceere\\Documents\\Hackathon\\projectcode\\facerecognition.py", line 212, in <module>\r\n    face_client.person_group.create(person_group_id=PERSON_GROUP_ID, name=PERSON_GROUP_ID)\r\n  File "C:\\Users\\Ceere\\AppData\\Local\\Programs\\Python\\Python39\\lib\\site-packages\\azure\\cognitiveservices\\vision\\face\\operations\\_person_group_operations.py", line 121, in create\r\n    raise models.APIErrorException(self._deserialize, response)\r\nazure.cognitiveservices.vision.face.models._models_py3.APIErrorException: (PersonGroupExists) Person group \'a066b34f-2968-4f63-8fea-f5a3bc437a75\' already exists.\r\n'
[I 220308 15:12:33 interface2:134] b'Person group: bfe66586-82a9-4384-961b-04955c7518c3\r\n[1, 13, 4, 5]\r\n[1, 13, 4, 5]\r\n[1, 13, 4, 5]\r\n[1, 13, 4, 5]\r\n\r\nTraining the person group...\r\nTraining status: succeeded.\r\n\r\nIdentifying faces in testimage.png\r\nPerson for face ID d18495bd-0ce3-4064-8155-34c69d3d5677 is identified in testimage.png with a confidence of 0.54927.\r\nPerson group: bfe66586-82a9-4384-961b-04955c7518c3\r\n'
[I 220308 15:12:33 interface2:139] b'Traceback (most recent call last):\r\n  File "C:\\Users\\Ceere\\Documents\\Hackathon\\projectcode\\facerecognition.py", line 212, in <module>\r\n    face_client.person_group.create(person_group_id=PERSON_GROUP_ID, name=PERSON_GROUP_ID)\r\n  File "C:\\Users\\Ceere\\AppData\\Local\\Programs\\Python\\Python39\\lib\\site-packages\\azure\\cognitiveservices\\vision\\face\\operations\\_person_group_operations.py", line 121, in create\r\n    raise models.APIErrorException(self._deserialize, response)\r\nazure.cognitiveservices.vision.face.models._models_py3.APIErrorException: (PersonGroupExists) Person group \'bfe66586-82a9-4384-961b-04955c7518c3\' already exists.\r\n'
[I 220308 15:15:38 interface2:134] b'Person group: ab9cf8c8-c742-4fa9-8d86-10d63e24a37a\r\n[3, 4, 13, 5]\r\n[3, 4, 13, 5]\r\n[3, 4, 13, 5]\r\n[3, 4, 13, 5]\r\n\r\nTraining the person group...\r\nTraining status: running.\r\n\r\nTraining status: succeeded.\r\n\r\nIdentifying faces in testimage.png\r\nPerson for face ID 96887e1e-4e4b-445d-a672-3250db3f24a7 is identified in testimage.png with a confidence of 0.64392.\r\nPerson group: ab9cf8c8-c742-4fa9-8d86-10d63e24a37a\r\n'
[I 220308 15:15:38 interface2:139] b'Traceback (most recent call last):\r\n  File "C:\\Users\\Ceere\\Documents\\Hackathon\\projectcode\\facerecognition.py", line 212, in <module>\r\n    face_client.person_group.create(person_group_id=PERSON_GROUP_ID, name=PERSON_GROUP_ID)\r\n  File "C:\\Users\\Ceere\\AppData\\Local\\Programs\\Python\\Python39\\lib\\site-packages\\azure\\cognitiveservices\\vision\\face\\operations\\_person_group_operations.py", line 121, in create\r\n    raise models.APIErrorException(self._deserialize, response)\r\nazure.cognitiveservices.vision.face.models._models_py3.APIErrorException: (PersonGroupExists) Person group \'ab9cf8c8-c742-4fa9-8d86-10d63e24a37a\' already exists.\r\n'
[I 220308 19:40:10 interface2:184] b'Person group: a4f1aef8-fadb-414a-9008-b3c560fa9cf3\r\n[9, 3, 5, 0]\r\n[9, 3, 5, 0]\r\n[9, 3, 5, 0]\r\n[9, 3, 5, 0]\r\n\r\nTraining the person group...\r\nTraining status: succeeded.\r\n\r\n'
[I 220308 19:40:11 interface2:189] b'Traceback (most recent call last):\r\n  File "C:\\Users\\Ceere\\Documents\\Hackathon\\projectcode\\facerecognition.py", line 166, in <module>\r\n    faces = face_client.face.detect_with_stream(image, detection_model=\'detection_03\')\r\n  File "C:\\Users\\Ceere\\AppData\\Local\\Programs\\Python\\Python39\\lib\\site-packages\\azure\\cognitiveservices\\vision\\face\\operations\\_face_operations.py", line 776, in detect_with_stream\r\n    raise models.APIErrorException(self._deserialize, response)\r\nazure.cognitiveservices.vision.face.models._models_py3.APIErrorException: (InvalidImageSize) Image size is too big.\r\n'
[I 220308 19:47:30 interface2:185] b'Person group: 8f0417df-54f9-4c86-96dc-f492b01b7203\r\n[3, 10, 13, 8]\r\n[3, 10, 13, 8]\r\n[3, 10, 13, 8]\r\n[3, 10, 13, 8]\r\n\r\nTraining the person group...\r\nTraining status: succeeded.\r\n\r\n'
[I 220308 19:47:30 interface2:190] b'Traceback (most recent call last):\r\n  File "C:\\Users\\Ceere\\Documents\\Hackathon\\projectcode\\facerecognition.py", line 166, in <module>\r\n    faces = face_client.face.detect_with_stream(image, detection_model=\'detection_03\')\r\n  File "C:\\Users\\Ceere\\AppData\\Local\\Programs\\Python\\Python39\\lib\\site-packages\\azure\\cognitiveservices\\vision\\face\\operations\\_face_operations.py", line 776, in detect_with_stream\r\n    raise models.APIErrorException(self._deserialize, response)\r\nazure.cognitiveservices.vision.face.models._models_py3.APIErrorException: (InvalidImageSize) Image size is too big.\r\n'
[I 220308 21:02:19 interface2:184] b'Person group: 69120799-f91d-4e18-a72f-6b388e330287\r\n[11, 1, 9, 13]\r\n[11, 1, 9, 13]\r\n[11, 1, 9, 13]\r\n[11, 1, 9, 13]\r\n\r\nTraining the person group...\r\nTraining status: succeeded.\r\n\r\n'
[I 220308 21:02:19 interface2:189] b'Traceback (most recent call last):\r\n  File "C:\\Users\\Ceere\\Documents\\Hackathon\\projectcode\\facerecognition.py", line 166, in <module>\r\n    faces = face_client.face.detect_with_stream(image, detection_model=\'detection_03\')\r\n  File "C:\\Users\\Ceere\\AppData\\Local\\Programs\\Python\\Python39\\lib\\site-packages\\azure\\cognitiveservices\\vision\\face\\operations\\_face_operations.py", line 776, in detect_with_stream\r\n    raise models.APIErrorException(self._deserialize, response)\r\nazure.cognitiveservices.vision.face.models._models_py3.APIErrorException: (InvalidImageSize) Image size is too big.\r\n'
[I 220308 21:14:32 interface2:185] b'Person group: de959a0d-4d32-40fd-bc92-110a63d8f960\r\n[12, 3, 1, 14]\r\n[12, 3, 1, 14]\r\n[12, 3, 1, 14]\r\n[12, 3, 1, 14]\r\n'
[I 220308 21:14:32 interface2:190] b'Traceback (most recent call last):\r\n  File "C:\\Users\\Ceere\\Documents\\Hackathon\\projectcode\\facerecognition.py", line 129, in <module>\r\n    face_client.person_group_person.add_face_from_stream(PERSON_GROUP_ID, janetceere.person_id,k)\r\n  File "C:\\Users\\Ceere\\AppData\\Local\\Programs\\Python\\Python39\\lib\\site-packages\\azure\\cognitiveservices\\vision\\face\\operations\\_person_group_person_operations.py", line 767, in add_face_from_stream\r\n    raise models.APIErrorException(self._deserialize, response)\r\nazure.cognitiveservices.vision.face.models._models_py3.APIErrorException: (InvalidImage) No face detected in the image.\r\n'
[I 220308 23:50:30 interface:134] b'Person group: 3d6948ef-1ec9-42be-9a22-e64fae68a476\r\n[5, 6, 4, 9]\r\n[5, 6, 4, 9]\r\n[5, 6, 4, 9]\r\n[5, 6, 4, 9]\r\n\r\nTraining the person group...\r\nTraining status: succeeded.\r\n\r\nIdentifying faces in testimage.png\r\nPerson group: 3d6948ef-1ec9-42be-9a22-e64fae68a476\r\n'
[I 220308 23:50:30 interface:139] b'Traceback (most recent call last):\r\n  File "C:\\Users\\Ceere\\Documents\\Hackathon\\projectcode\\facerecognition.py", line 216, in <module>\r\n    face_client.person_group.create(person_group_id=PERSON_GROUP_ID, name=PERSON_GROUP_ID)\r\n  File "C:\\Users\\Ceere\\AppData\\Local\\Programs\\Python\\Python39\\lib\\site-packages\\azure\\cognitiveservices\\vision\\face\\operations\\_person_group_operations.py", line 121, in create\r\n    raise models.APIErrorException(self._deserialize, response)\r\nazure.cognitiveservices.vision.face.models._models_py3.APIErrorException: (PersonGroupExists) Person group \'3d6948ef-1ec9-42be-9a22-e64fae68a476\' already exists.\r\n'
[I 220309 01:02:41 interface:185] b'Person group: 24b38c4f-7390-4452-86bb-70b15a63045a\r\n[11, 3, 2, 13]\r\n[11, 3, 2, 13]\r\n[11, 3, 2, 13]\r\n[11, 3, 2, 13]\r\n\r\nTraining the person group...\r\nTraining status: running.\r\n\r\nTraining status: succeeded.\r\n\r\nIdentifying faces in testimage.png\r\nPerson group: 24b38c4f-7390-4452-86bb-70b15a63045a\r\n'
[I 220309 01:02:41 interface:190] b'Traceback (most recent call last):\r\n  File "C:\\Users\\Ceere\\Documents\\Hackathon\\projectcode\\facerecognition.py", line 216, in <module>\r\n    face_client.person_group.create(person_group_id=PERSON_GROUP_ID, name=PERSON_GROUP_ID)\r\n  File "C:\\Users\\Ceere\\AppData\\Local\\Programs\\Python\\Python39\\lib\\site-packages\\azure\\cognitiveservices\\vision\\face\\operations\\_person_group_operations.py", line 121, in create\r\n    raise models.APIErrorException(self._deserialize, response)\r\nazure.cognitiveservices.vision.face.models._models_py3.APIErrorException: (PersonGroupExists) Person group \'24b38c4f-7390-4452-86bb-70b15a63045a\' already exists.\r\n'
[I 220317 12:53:08 interface:185] b'Person group: dda1d933-558c-458c-9607-54523c804f95\r\n[2, 0, 9, 3]\r\n[2, 0, 9, 3]\r\n'
[I 220317 12:53:08 interface:190] b'Traceback (most recent call last):\r\n  File "C:\\Users\\Ceere\\Documents\\Hackathon\\projectcode\\facerecognition.py", line 129, in <module>\r\n    face_client.person_group_person.add_face_from_stream(PERSON_GROUP_ID, janetceere.person_id,k)\r\n  File "C:\\Users\\Ceere\\AppData\\Local\\Programs\\Python\\Python39\\lib\\site-packages\\azure\\cognitiveservices\\vision\\face\\operations\\_person_group_person_operations.py", line 767, in add_face_from_stream\r\n    raise models.APIErrorException(self._deserialize, response)\r\nazure.cognitiveservices.vision.face.models._models_py3.APIErrorException: (InvalidImage) No face detected in the image.\r\n'
[I 220317 13:12:43 interface:185] b'Person group: 158ba6b2-c601-4e1a-be58-c6dd50811001\r\n[12, 1, 3, 6]\r\n[12, 1, 3, 6]\r\n[12, 1, 3, 6]\r\n[12, 1, 3, 6]\r\n\r\nTraining the person group...\r\nTraining status: succeeded.\r\n\r\nIdentifying faces in testimage.png\r\nPerson group: 158ba6b2-c601-4e1a-be58-c6dd50811001\r\n'
[I 220317 13:12:43 interface:190] b'Traceback (most recent call last):\r\n  File "C:\\Users\\Ceere\\Documents\\Hackathon\\projectcode\\facerecognition.py", line 216, in <module>\r\n    face_client.person_group.create(person_group_id=PERSON_GROUP_ID, name=PERSON_GROUP_ID)\r\n  File "C:\\Users\\Ceere\\AppData\\Local\\Programs\\Python\\Python39\\lib\\site-packages\\azure\\cognitiveservices\\vision\\face\\operations\\_person_group_operations.py", line 121, in create\r\n    raise models.APIErrorException(self._deserialize, response)\r\nazure.cognitiveservices.vision.face.models._models_py3.APIErrorException: (PersonGroupExists) Person group \'158ba6b2-c601-4e1a-be58-c6dd50811001\' already exists.\r\n'
[I 220317 13:17:18 interface:184] b'Person group: ba19f537-299b-43b5-97df-4c705b27479c\r\n[12, 11, 14, 5]\r\n[12, 11, 14, 5]\r\n[12, 11, 14, 5]\r\n'
[I 220317 13:17:18 interface:189] b'Traceback (most recent call last):\r\n  File "C:\\Users\\Ceere\\Documents\\Hackathon\\projectcode\\facerecognition.py", line 129, in <module>\r\n    face_client.person_group_person.add_face_from_stream(PERSON_GROUP_ID, janetceere.person_id,k)\r\n  File "C:\\Users\\Ceere\\AppData\\Local\\Programs\\Python\\Python39\\lib\\site-packages\\azure\\cognitiveservices\\vision\\face\\operations\\_person_group_person_operations.py", line 767, in add_face_from_stream\r\n    raise models.APIErrorException(self._deserialize, response)\r\nazure.cognitiveservices.vision.face.models._models_py3.APIErrorException: (InvalidImage) No face detected in the image.\r\n'
[I 220317 13:20:39 interface:184] b'Person group: adb1165d-ec35-4d11-b983-9d2c1b5361d8\r\n[1, 7, 0, 5]\r\n[1, 7, 0, 5]\r\n[1, 7, 0, 5]\r\n[1, 7, 0, 5]\r\n\r\nTraining the person group...\r\nTraining status: succeeded.\r\n\r\nIdentifying faces in testimage.png\r\nPerson for face ID ab43d4e1-c0b6-4b1d-a2fd-dfd3407617a6 is identified in testimage.png with a confidence of 0.51203.\r\nPerson group: adb1165d-ec35-4d11-b983-9d2c1b5361d8\r\n'
[I 220317 13:20:39 interface:189] b'Traceback (most recent call last):\r\n  File "C:\\Users\\Ceere\\Documents\\Hackathon\\projectcode\\facerecognition.py", line 216, in <module>\r\n    face_client.person_group.create(person_group_id=PERSON_GROUP_ID, name=PERSON_GROUP_ID)\r\n  File "C:\\Users\\Ceere\\AppData\\Local\\Programs\\Python\\Python39\\lib\\site-packages\\azure\\cognitiveservices\\vision\\face\\operations\\_person_group_operations.py", line 121, in create\r\n    raise models.APIErrorException(self._deserialize, response)\r\nazure.cognitiveservices.vision.face.models._models_py3.APIErrorException: (PersonGroupExists) Person group \'adb1165d-ec35-4d11-b983-9d2c1b5361d8\' already exists.\r\n'
[I 220317 13:25:37 interface:184] b'Person group: 600d5f46-d6a6-4adf-9560-c35ce8b7b83b\r\n[4, 7, 2, 12]\r\n[4, 7, 2, 12]\r\n[4, 7, 2, 12]\r\n[4, 7, 2, 12]\r\n\r\nTraining the person group...\r\nTraining status: succeeded.\r\n\r\nIdentifying faces in testimage.png\r\nPerson group: 600d5f46-d6a6-4adf-9560-c35ce8b7b83b\r\n'
[I 220317 13:25:37 interface:189] b'Traceback (most recent call last):\r\n  File "C:\\Users\\Ceere\\Documents\\Hackathon\\projectcode\\facerecognition.py", line 216, in <module>\r\n    face_client.person_group.create(person_group_id=PERSON_GROUP_ID, name=PERSON_GROUP_ID)\r\n  File "C:\\Users\\Ceere\\AppData\\Local\\Programs\\Python\\Python39\\lib\\site-packages\\azure\\cognitiveservices\\vision\\face\\operations\\_person_group_operations.py", line 121, in create\r\n    raise models.APIErrorException(self._deserialize, response)\r\nazure.cognitiveservices.vision.face.models._models_py3.APIErrorException: (PersonGroupExists) Person group \'600d5f46-d6a6-4adf-9560-c35ce8b7b83b\' already exists.\r\n'
[I 220317 13:29:19 interface:184] b'Person group: a8e3e3d6-ef94-41a7-8976-2e903f048eea\r\n[3, 14, 9, 1]\r\n[3, 14, 9, 1]\r\n'
[I 220317 13:29:19 interface:189] b'Traceback (most recent call last):\r\n  File "C:\\Users\\Ceere\\Documents\\Hackathon\\projectcode\\facerecognition.py", line 129, in <module>\r\n    face_client.person_group_person.add_face_from_stream(PERSON_GROUP_ID, janetceere.person_id,k)\r\n  File "C:\\Users\\Ceere\\AppData\\Local\\Programs\\Python\\Python39\\lib\\site-packages\\azure\\cognitiveservices\\vision\\face\\operations\\_person_group_person_operations.py", line 767, in add_face_from_stream\r\n    raise models.APIErrorException(self._deserialize, response)\r\nazure.cognitiveservices.vision.face.models._models_py3.APIErrorException: (InvalidImage) No face detected in the image.\r\n'
[I 220317 13:31:53 interface:184] b'Person group: 3cdd826e-02e5-4981-9c61-4bdc6924d6d4\r\n[6, 13, 11, 4]\r\n[6, 13, 11, 4]\r\n[6, 13, 11, 4]\r\n[6, 13, 11, 4]\r\n\r\nTraining the person group...\r\nTraining status: running.\r\n\r\nTraining status: succeeded.\r\n\r\nIdentifying faces in testimage.png\r\nUnidentified person for face ID 5bf114b5-f7c0-493e-9868-e00b7613201f in testimage.png.\r\nPerson group: 3cdd826e-02e5-4981-9c61-4bdc6924d6d4\r\n'
[I 220317 13:31:53 interface:189] b'Traceback (most recent call last):\r\n  File "C:\\Users\\Ceere\\Documents\\Hackathon\\projectcode\\facerecognition.py", line 216, in <module>\r\n    face_client.person_group.create(person_group_id=PERSON_GROUP_ID, name=PERSON_GROUP_ID)\r\n  File "C:\\Users\\Ceere\\AppData\\Local\\Programs\\Python\\Python39\\lib\\site-packages\\azure\\cognitiveservices\\vision\\face\\operations\\_person_group_operations.py", line 121, in create\r\n    raise models.APIErrorException(self._deserialize, response)\r\nazure.cognitiveservices.vision.face.models._models_py3.APIErrorException: (PersonGroupExists) Person group \'3cdd826e-02e5-4981-9c61-4bdc6924d6d4\' already exists.\r\n'
[I 220317 14:52:19 interface:184] b'Person group: 9027e38c-47c2-4d4e-97e9-893014205a32\r\n[2, 5, 7, 3]\r\n[2, 5, 7, 3]\r\n[2, 5, 7, 3]\r\n[2, 5, 7, 3]\r\n\r\nTraining the person group...\r\nTraining status: running.\r\n\r\nTraining status: succeeded.\r\n\r\nIdentifying faces in testimage.png\r\nPerson group: 9027e38c-47c2-4d4e-97e9-893014205a32\r\n'
[I 220317 14:52:19 interface:189] b'Traceback (most recent call last):\r\n  File "C:\\Users\\Ceere\\Documents\\Hackathon\\projectcode\\facerecognition.py", line 216, in <module>\r\n    face_client.person_group.create(person_group_id=PERSON_GROUP_ID, name=PERSON_GROUP_ID)\r\n  File "C:\\Users\\Ceere\\AppData\\Local\\Programs\\Python\\Python39\\lib\\site-packages\\azure\\cognitiveservices\\vision\\face\\operations\\_person_group_operations.py", line 121, in create\r\n    raise models.APIErrorException(self._deserialize, response)\r\nazure.cognitiveservices.vision.face.models._models_py3.APIErrorException: (PersonGroupExists) Person group \'9027e38c-47c2-4d4e-97e9-893014205a32\' already exists.\r\n'
[I 220317 16:34:26 interface:184] b'Person group: fecec107-83d4-4c6a-b012-9f9fa531e0ee\r\n[8, 5, 14, 9]\r\n[8, 5, 14, 9]\r\n'
[I 220317 16:34:26 interface:189] b'Traceback (most recent call last):\r\n  File "C:\\Users\\Ceere\\Documents\\Hackathon\\projectcode\\facerecognition.py", line 73, in <module>\r\n    face_client.person_group_person.add_face_from_stream(PERSON_GROUP_ID, janetceere.person_id,k)\r\n  File "C:\\Users\\Ceere\\AppData\\Local\\Programs\\Python\\Python39\\lib\\site-packages\\azure\\cognitiveservices\\vision\\face\\operations\\_person_group_person_operations.py", line 767, in add_face_from_stream\r\n    raise models.APIErrorException(self._deserialize, response)\r\nazure.cognitiveservices.vision.face.models._models_py3.APIErrorException: (InvalidImage) No face detected in the image.\r\n'
[I 220317 16:36:40 interface:184] b'Person group: 6e67f616-8deb-407b-83fe-4759769d66e0\r\n[2, 9, 14, 7]\r\n[2, 9, 14, 7]\r\n[2, 9, 14, 7]\r\n'
[I 220317 16:36:40 interface:189] b'Traceback (most recent call last):\r\n  File "C:\\Users\\Ceere\\Documents\\Hackathon\\projectcode\\facerecognition.py", line 73, in <module>\r\n    face_client.person_group_person.add_face_from_stream(PERSON_GROUP_ID, janetceere.person_id,k)\r\n  File "C:\\Users\\Ceere\\AppData\\Local\\Programs\\Python\\Python39\\lib\\site-packages\\azure\\cognitiveservices\\vision\\face\\operations\\_person_group_person_operations.py", line 767, in add_face_from_stream\r\n    raise models.APIErrorException(self._deserialize, response)\r\nazure.cognitiveservices.vision.face.models._models_py3.APIErrorException: (InvalidImage) No face detected in the image.\r\n'
[I 220317 16:38:55 interface:184] b'Person group: 3e4c0b9b-2ee9-4f1e-85fb-d717a1bf44d8\r\n[6, 5, 1, 9]\r\n[6, 5, 1, 9]\r\n[6, 5, 1, 9]\r\n[6, 5, 1, 9]\r\n\r\nTraining the person group...\r\nTraining status: succeeded.\r\n\r\nIdentifying faces in testimage.png\r\n'
[I 220317 16:42:30 interface:184] b'Person group: 7caa94d5-88c7-4cab-9ef1-9950a9c449f4\r\n[2, 5, 0, 8]\r\n[2, 5, 0, 8]\r\n[2, 5, 0, 8]\r\n[2, 5, 0, 8]\r\n\r\nTraining the person group...\r\nTraining status: succeeded.\r\n\r\nIdentifying faces in testimage.png\r\n'
[I 220317 16:48:36 interface:184] b'Person group: 67e5b5c1-79fd-4283-84dd-e0e7b05632f4\r\n[10, 6, 3, 11]\r\n[10, 6, 3, 11]\r\n[10, 6, 3, 11]\r\n[10, 6, 3, 11]\r\n\r\nTraining the person group...\r\nTraining status: succeeded.\r\n\r\n'
[I 220317 16:48:36 interface:189] b'Traceback (most recent call last):\r\n  File "C:\\Users\\Ceere\\Documents\\Hackathon\\projectcode\\facerecognition.py", line 110, in <module>\r\n    faces = face_client.face.detect_with_stream(image, detection_model=\'detection_03\')\r\n  File "C:\\Users\\Ceere\\AppData\\Local\\Programs\\Python\\Python39\\lib\\site-packages\\azure\\cognitiveservices\\vision\\face\\operations\\_face_operations.py", line 776, in detect_with_stream\r\n    raise models.APIErrorException(self._deserialize, response)\r\nazure.cognitiveservices.vision.face.models._models_py3.APIErrorException: (InvalidImageSize) Image size is too big.\r\n'
[I 220317 16:51:21 interface:184] b'Person group: d53bc8cf-db67-43a7-94ec-ec8ade182aa2\r\n[4, 9, 1, 3]\r\n[4, 9, 1, 3]\r\n[4, 9, 1, 3]\r\n[4, 9, 1, 3]\r\n\r\nTraining the person group...\r\nTraining status: succeeded.\r\n\r\n'
[I 220317 16:51:21 interface:189] b'Traceback (most recent call last):\r\n  File "C:\\Users\\Ceere\\Documents\\Hackathon\\projectcode\\facerecognition.py", line 110, in <module>\r\n    faces = face_client.face.detect_with_stream(image, detection_model=\'detection_03\')\r\n  File "C:\\Users\\Ceere\\AppData\\Local\\Programs\\Python\\Python39\\lib\\site-packages\\azure\\cognitiveservices\\vision\\face\\operations\\_face_operations.py", line 776, in detect_with_stream\r\n    raise models.APIErrorException(self._deserialize, response)\r\nazure.cognitiveservices.vision.face.models._models_py3.APIErrorException: (InvalidImageSize) Image size is too big.\r\n'
[I 220317 16:54:43 interface:184] b'Person group: ca7cc478-a5c2-49ca-a799-0e064ddaa688\r\n[5, 7, 2, 12]\r\n[5, 7, 2, 12]\r\n[5, 7, 2, 12]\r\n[5, 7, 2, 12]\r\n\r\nTraining the person group...\r\nTraining status: running.\r\n\r\nTraining status: succeeded.\r\n\r\nIdentifying faces in testimage.png\r\nPerson for face ID adf9a542-af00-4686-94b3-672b840ff1bd is identified in testimage.png with a confidence of 0.54187.\r\n'
[I 220317 16:56:21 interface:184] b'Person group: e08827ce-1bb4-4040-b62a-72d1b6e2ecff\r\n[5, 3, 4, 9]\r\n[5, 3, 4, 9]\r\n[5, 3, 4, 9]\r\n[5, 3, 4, 9]\r\n'
[I 220317 16:56:21 interface:189] b'Traceback (most recent call last):\r\n  File "C:\\Users\\Ceere\\Documents\\Hackathon\\projectcode\\facerecognition.py", line 73, in <module>\r\n    face_client.person_group_person.add_face_from_stream(PERSON_GROUP_ID, janetceere.person_id,k)\r\n  File "C:\\Users\\Ceere\\AppData\\Local\\Programs\\Python\\Python39\\lib\\site-packages\\azure\\cognitiveservices\\vision\\face\\operations\\_person_group_person_operations.py", line 767, in add_face_from_stream\r\n    raise models.APIErrorException(self._deserialize, response)\r\nazure.cognitiveservices.vision.face.models._models_py3.APIErrorException: (InvalidImage) There is more than 1 face in the image.\r\n'
[I 220317 16:59:21 interface:184] b'Person group: 615f7d30-fc87-4040-98ee-e78641a8aa2a\r\n[13, 3, 8, 14]\r\n[13, 3, 8, 14]\r\n[13, 3, 8, 14]\r\n[13, 3, 8, 14]\r\n'
[I 220317 16:59:21 interface:189] b'Traceback (most recent call last):\r\n  File "C:\\Users\\Ceere\\Documents\\Hackathon\\projectcode\\facerecognition.py", line 73, in <module>\r\n    face_client.person_group_person.add_face_from_stream(PERSON_GROUP_ID, janetceere.person_id,k)\r\n  File "C:\\Users\\Ceere\\AppData\\Local\\Programs\\Python\\Python39\\lib\\site-packages\\azure\\cognitiveservices\\vision\\face\\operations\\_person_group_person_operations.py", line 767, in add_face_from_stream\r\n    raise models.APIErrorException(self._deserialize, response)\r\nazure.cognitiveservices.vision.face.models._models_py3.APIErrorException: (InvalidImage) No face detected in the image.\r\n'
[I 220317 17:53:24 interface:184] b'Person group: be4d4334-a76e-42f7-b416-2a40ba5387f8\r\n[12, 14, 3, 5]\r\n[12, 14, 3, 5]\r\n'
[I 220317 17:53:24 interface:189] b'Traceback (most recent call last):\r\n  File "C:\\Users\\Ceere\\Documents\\Hackathon\\projectcode\\facerecognition.py", line 73, in <module>\r\n    face_client.person_group_person.add_face_from_stream(PERSON_GROUP_ID, janetceere.person_id,k)\r\n  File "C:\\Users\\Ceere\\AppData\\Local\\Programs\\Python\\Python39\\lib\\site-packages\\azure\\cognitiveservices\\vision\\face\\operations\\_person_group_person_operations.py", line 767, in add_face_from_stream\r\n    raise models.APIErrorException(self._deserialize, response)\r\nazure.cognitiveservices.vision.face.models._models_py3.APIErrorException: (InvalidImage) No face detected in the image.\r\n'
[I 220317 17:56:46 interface:184] b'Person group: b4bdb2c8-7ded-4497-bcd4-552b734fd51c\r\n[12, 11, 14, 3]\r\n[12, 11, 14, 3]\r\n[12, 11, 14, 3]\r\n'
[I 220317 17:56:46 interface:189] b'Traceback (most recent call last):\r\n  File "C:\\Users\\Ceere\\Documents\\Hackathon\\projectcode\\facerecognition.py", line 73, in <module>\r\n    face_client.person_group_person.add_face_from_stream(PERSON_GROUP_ID, janetceere.person_id,k)\r\n  File "C:\\Users\\Ceere\\AppData\\Local\\Programs\\Python\\Python39\\lib\\site-packages\\azure\\cognitiveservices\\vision\\face\\operations\\_person_group_person_operations.py", line 767, in add_face_from_stream\r\n    raise models.APIErrorException(self._deserialize, response)\r\nazure.cognitiveservices.vision.face.models._models_py3.APIErrorException: (InvalidImage) No face detected in the image.\r\n'
[I 220317 17:59:09 interface:184] b'Person group: 9ee3425b-52df-4fb5-990b-a5e9decaa1a0\r\n[12, 14, 3, 4]\r\n[12, 14, 3, 4]\r\n'
[I 220317 17:59:09 interface:189] b'Traceback (most recent call last):\r\n  File "C:\\Users\\Ceere\\Documents\\Hackathon\\projectcode\\facerecognition.py", line 73, in <module>\r\n    face_client.person_group_person.add_face_from_stream(PERSON_GROUP_ID, janetceere.person_id,k)\r\n  File "C:\\Users\\Ceere\\AppData\\Local\\Programs\\Python\\Python39\\lib\\site-packages\\azure\\cognitiveservices\\vision\\face\\operations\\_person_group_person_operations.py", line 767, in add_face_from_stream\r\n    raise models.APIErrorException(self._deserialize, response)\r\nazure.cognitiveservices.vision.face.models._models_py3.APIErrorException: (InvalidImage) No face detected in the image.\r\n'
[I 220317 18:01:52 interface:184] b'Person group: ae4156a2-8f37-46e8-947e-f2af029aae39\r\n[3, 10, 11, 6]\r\n[3, 10, 11, 6]\r\n[3, 10, 11, 6]\r\n[3, 10, 11, 6]\r\n'
[I 220317 18:01:52 interface:189] b'Traceback (most recent call last):\r\n  File "C:\\Users\\Ceere\\Documents\\Hackathon\\projectcode\\facerecognition.py", line 73, in <module>\r\n    face_client.person_group_person.add_face_from_stream(PERSON_GROUP_ID, janetceere.person_id,k)\r\n  File "C:\\Users\\Ceere\\AppData\\Local\\Programs\\Python\\Python39\\lib\\site-packages\\azure\\cognitiveservices\\vision\\face\\operations\\_person_group_person_operations.py", line 767, in add_face_from_stream\r\n    raise models.APIErrorException(self._deserialize, response)\r\nazure.cognitiveservices.vision.face.models._models_py3.APIErrorException: (InvalidImage) No face detected in the image.\r\n'
[I 220317 18:05:39 interface:184] b'Person group: 5751ef0e-a739-4b61-a30e-bb07ad279101\r\n[11, 8, 7, 4]\r\n[11, 8, 7, 4]\r\n[11, 8, 7, 4]\r\n[11, 8, 7, 4]\r\n\r\nTraining the person group...\r\nTraining status: running.\r\n\r\nTraining status: succeeded.\r\n\r\nIdentifying faces in testimage.png\r\nPerson for face ID 1a2db94e-aa8b-4dd3-826f-0a09d9e262db is identified in testimage.png with a confidence of 0.62209.\r\n'
[I 220317 18:08:32 interface:184] b'Person group: cca0030d-1cb0-46c6-8fb4-fa8b55355d1d\r\n[8, 5, 3, 4]\r\n[8, 5, 3, 4]\r\n[8, 5, 3, 4]\r\n[8, 5, 3, 4]\r\n\r\nTraining the person group...\r\nTraining status: succeeded.\r\n\r\nIdentifying faces in testimage.png\r\n'
[I 220519 10:44:40 interface:184] b'Person group: 542121b4-3e85-489e-98bb-03d2e92304df\r\n[6, 7, 11, 13]\r\n[6, 7, 11, 13]\r\n[6, 7, 11, 13]\r\n[6, 7, 11, 13]\r\n\r\nTraining the person group...\r\nTraining status: succeeded.\r\n\r\nIdentifying faces in testimage.png\r\nPerson for face ID c9aa5316-f150-4f3e-b564-00abd889d43e is identified in testimage.png with a confidence of 0.6617.\r\n'
[I 220519 10:54:54 interface:184] b'Person group: 5aa04e72-ed28-464b-80a1-0b0c2fb7facb\r\n[3, 13, 1, 5]\r\n[3, 13, 1, 5]\r\n[3, 13, 1, 5]\r\n[3, 13, 1, 5]\r\n\r\nTraining the person group...\r\nTraining status: succeeded.\r\n\r\n'
[I 220519 10:54:54 interface:189] b'Traceback (most recent call last):\r\n  File "C:\\Users\\Ceere\\Documents\\computer Science\\fourth year docs\\project\\projectCode\\facerecognition.py", line 110, in <module>\r\n    faces = face_client.face.detect_with_stream(image, detection_model=\'detection_03\')\r\n  File "C:\\Users\\Ceere\\AppData\\Local\\Programs\\Python\\Python39\\lib\\site-packages\\azure\\cognitiveservices\\vision\\face\\operations\\_face_operations.py", line 776, in detect_with_stream\r\n    raise models.APIErrorException(self._deserialize, response)\r\nazure.cognitiveservices.vision.face.models._models_py3.APIErrorException: (InvalidImageSize) Image size is too big.\r\n'
[I 220519 11:08:43 interface:184] b'Person group: 6a04cb65-7530-4f53-ab16-77c030f6780f\r\n[8, 7, 3, 5]\r\n[8, 7, 3, 5]\r\n[8, 7, 3, 5]\r\n[8, 7, 3, 5]\r\n\r\nTraining the person group...\r\nTraining status: running.\r\n\r\nTraining status: succeeded.\r\n\r\n'
[I 220519 11:08:43 interface:189] b'Traceback (most recent call last):\r\n  File "C:\\Users\\Ceere\\Documents\\computer Science\\fourth year docs\\project\\projectcodefinal\\facerecognition.py", line 116, in <module>\r\n    results = face_client.face.identify(face_ids, PERSON_GROUP_ID)\r\n  File "C:\\Users\\Ceere\\AppData\\Local\\Programs\\Python\\Python39\\lib\\site-packages\\azure\\cognitiveservices\\vision\\face\\operations\\_face_operations.py", line 316, in identify\r\n    raise models.APIErrorException(self._deserialize, response)\r\nazure.cognitiveservices.vision.face.models._models_py3.APIErrorException: (BadArgument) The length of faceIds is not in a valid range.\r\n'
[I 220519 11:15:20 interface:184] b'Person group: 14427ebe-23dc-47ec-a967-dbc8dfcf7322\r\n[14, 13, 2, 10]\r\n'
[I 220519 11:15:20 interface:189] b'Traceback (most recent call last):\r\n  File "C:\\Users\\Ceere\\Documents\\computer Science\\fourth year docs\\project\\projectcodefinal\\facerecognition.py", line 73, in <module>\r\n    face_client.person_group_person.add_face_from_stream(PERSON_GROUP_ID, janetceere.person_id,k)\r\n  File "C:\\Users\\Ceere\\AppData\\Local\\Programs\\Python\\Python39\\lib\\site-packages\\azure\\cognitiveservices\\vision\\face\\operations\\_person_group_person_operations.py", line 767, in add_face_from_stream\r\n    raise models.APIErrorException(self._deserialize, response)\r\nazure.cognitiveservices.vision.face.models._models_py3.APIErrorException: (InvalidImage) No face detected in the image.\r\n'
[I 220519 11:17:49 interface:184] b'Person group: 5931cef9-6dbd-4592-bd57-3b409ae82663\r\n[5, 11, 12, 9]\r\n[5, 11, 12, 9]\r\n[5, 11, 12, 9]\r\n[5, 11, 12, 9]\r\n\r\nTraining the person group...\r\nTraining status: running.\r\n\r\nTraining status: succeeded.\r\n\r\nIdentifying faces in testimage.png\r\n'
[I 220519 11:20:14 interface:184] b'Person group: 7ed0fa2b-ee1a-48a4-abf9-cec98d11d2c1\r\n[5, 9, 10, 0]\r\n[5, 9, 10, 0]\r\n[5, 9, 10, 0]\r\n[5, 9, 10, 0]\r\n\r\nTraining the person group...\r\nTraining status: running.\r\n\r\nTraining status: succeeded.\r\n\r\n'
[I 220519 11:20:14 interface:189] b'Traceback (most recent call last):\r\n  File "C:\\Users\\Ceere\\Documents\\computer Science\\fourth year docs\\project\\projectcodefinal\\facerecognition.py", line 110, in <module>\r\n    faces = face_client.face.detect_with_stream(image, detection_model=\'detection_03\')\r\n  File "C:\\Users\\Ceere\\AppData\\Local\\Programs\\Python\\Python39\\lib\\site-packages\\azure\\cognitiveservices\\vision\\face\\operations\\_face_operations.py", line 776, in detect_with_stream\r\n    raise models.APIErrorException(self._deserialize, response)\r\nazure.cognitiveservices.vision.face.models._models_py3.APIErrorException: (InvalidImageSize) Image size is too big.\r\n'
[I 220519 11:23:05 interface:184] b'Person group: a6ca08f0-2ae7-44a0-83c4-e6e8a6a55ded\r\n[4, 2, 0, 14]\r\n[4, 2, 0, 14]\r\n[4, 2, 0, 14]\r\n[4, 2, 0, 14]\r\n'
[I 220519 11:23:05 interface:189] b'Traceback (most recent call last):\r\n  File "C:\\Users\\Ceere\\Documents\\computer Science\\fourth year docs\\project\\projectcodefinal\\facerecognition.py", line 73, in <module>\r\n    face_client.person_group_person.add_face_from_stream(PERSON_GROUP_ID, janetceere.person_id,k)\r\n  File "C:\\Users\\Ceere\\AppData\\Local\\Programs\\Python\\Python39\\lib\\site-packages\\azure\\cognitiveservices\\vision\\face\\operations\\_person_group_person_operations.py", line 767, in add_face_from_stream\r\n    raise models.APIErrorException(self._deserialize, response)\r\nazure.cognitiveservices.vision.face.models._models_py3.APIErrorException: (InvalidImage) No face detected in the image.\r\n'
[I 220519 11:25:37 interface:184] b'Person group: 42b25005-1bba-4b1c-9a51-0e524ea36748\r\n[9, 3, 5, 4]\r\n[9, 3, 5, 4]\r\n[9, 3, 5, 4]\r\n[9, 3, 5, 4]\r\n\r\nTraining the person group...\r\nTraining status: running.\r\n\r\nTraining status: succeeded.\r\n\r\nIdentifying faces in testimage.png\r\nPerson for face ID 76c38027-c08d-4952-92f7-9d6e4e433447 is identified in testimage.png with a confidence of 0.66065.\r\n'
[I 220519 11:30:28 interface:184] b'Person group: 4d28fae5-bdbb-4038-ae87-2475a3588565\r\n[13, 9, 1, 14]\r\n[13, 9, 1, 14]\r\n[13, 9, 1, 14]\r\n[13, 9, 1, 14]\r\n'
[I 220519 11:30:28 interface:189] b'Traceback (most recent call last):\r\n  File "C:\\Users\\Ceere\\Documents\\computer Science\\fourth year docs\\project\\projectcodefinal\\facerecognition.py", line 73, in <module>\r\n    face_client.person_group_person.add_face_from_stream(PERSON_GROUP_ID, janetceere.person_id,k)\r\n  File "C:\\Users\\Ceere\\AppData\\Local\\Programs\\Python\\Python39\\lib\\site-packages\\azure\\cognitiveservices\\vision\\face\\operations\\_person_group_person_operations.py", line 767, in add_face_from_stream\r\n    raise models.APIErrorException(self._deserialize, response)\r\nazure.cognitiveservices.vision.face.models._models_py3.APIErrorException: (InvalidImage) No face detected in the image.\r\n'
[I 220519 11:32:25 interface:184] b'Person group: 767ed090-2750-4d54-a9f8-d6f6a4b3f0a5\r\n[0, 11, 8, 10]\r\n[0, 11, 8, 10]\r\n[0, 11, 8, 10]\r\n[0, 11, 8, 10]\r\n\r\nTraining the person group...\r\nTraining status: succeeded.\r\n\r\nIdentifying faces in testimage.png\r\nPerson for face ID 4f34581e-6425-4f81-8c29-712f5ce547c4 is identified in testimage.png with a confidence of 0.63281.\r\n'
[I 220519 14:23:16 interface:184] b"Person group: 78b7ef17-cd6b-4c62-9616-ee23dfa7ee63\r\n[6, 9, 11, 0]\r\n[6, 9, 11, 0]\r\n[6, 9, 11, 0]\r\n[6, 9, 11, 0]\r\n\r\nTraining the person group...\r\nTraining status: succeeded.\r\n\r\nIdentifying faces in testimage.png\r\nPerson for face ID e029e0fa-eddf-4f99-8d61-2e2ac7d9a7c4 is identified in testimage.png with a confidence of 0.59125.\r\n[ WARN:0] global C:\\Users\\runneradmin\\AppData\\Local\\Temp\\pip-req-build-sn_xpupm\\opencv\\modules\\videoio\\src\\cap_msmf.cpp (438) `anonymous-namespace'::SourceReaderCB::~SourceReaderCB terminating async callback\r\r\n\r\n"
[I 220519 14:37:51 interface:184] b'Person group: 9ba3600e-fbaa-4bb0-963c-1f173892b63b\r\n[6, 12, 14, 13]\r\n[6, 12, 14, 13]\r\n[6, 12, 14, 13]\r\n'
[I 220519 14:37:51 interface:189] b'Traceback (most recent call last):\r\n  File "C:\\Users\\Ceere\\Documents\\computer Science\\fourth year docs\\project\\projectcodefinal\\facerecognition.py", line 74, in <module>\r\n    face_client.person_group_person.add_face_from_stream(PERSON_GROUP_ID, janetceere.person_id,k)\r\n  File "C:\\Users\\Ceere\\AppData\\Local\\Programs\\Python\\Python39\\lib\\site-packages\\azure\\cognitiveservices\\vision\\face\\operations\\_person_group_person_operations.py", line 767, in add_face_from_stream\r\n    raise models.APIErrorException(self._deserialize, response)\r\nazure.cognitiveservices.vision.face.models._models_py3.APIErrorException: (InvalidImage) No face detected in the image.\r\n'
[I 220519 14:39:50 interface:184] b'Person group: b8d24d53-ceb6-4021-be4f-dca34d1c021f\r\n[9, 3, 6, 0]\r\n[9, 3, 6, 0]\r\n[9, 3, 6, 0]\r\n[9, 3, 6, 0]\r\n\r\nTraining the person group...\r\nTraining status: succeeded.\r\n\r\nIdentifying faces in testimage.png\r\nPerson for face ID d3f3de72-e777-4c3b-b0d9-b7a87c736781 is identified in testimage.png with a confidence of 0.66501.\r\n'
[I 220519 15:12:24 interface:184] b'Person group: 6d6110b3-5d27-435e-85d4-213e129b4150\r\n[0, 4, 14, 10]\r\n[0, 4, 14, 10]\r\n[0, 4, 14, 10]\r\n'
[I 220519 15:12:24 interface:189] b'Traceback (most recent call last):\r\n  File "C:\\Users\\Ceere\\Documents\\computer Science\\fourth year docs\\project\\projectcodefinal\\facerecognition.py", line 74, in <module>\r\n    face_client.person_group_person.add_face_from_stream(PERSON_GROUP_ID, janetceere.person_id,k)\r\n  File "C:\\Users\\Ceere\\AppData\\Local\\Programs\\Python\\Python39\\lib\\site-packages\\azure\\cognitiveservices\\vision\\face\\operations\\_person_group_person_operations.py", line 767, in add_face_from_stream\r\n    raise models.APIErrorException(self._deserialize, response)\r\nazure.cognitiveservices.vision.face.models._models_py3.APIErrorException: (InvalidImage) No face detected in the image.\r\n'
[I 220519 15:14:18 interface:184] b'Person group: 85526acd-b110-47f5-a13e-2e03296d7783\r\n[7, 1, 14, 9]\r\n[7, 1, 14, 9]\r\n[7, 1, 14, 9]\r\n'
[I 220519 15:14:18 interface:189] b'Traceback (most recent call last):\r\n  File "C:\\Users\\Ceere\\Documents\\computer Science\\fourth year docs\\project\\projectcodefinal\\facerecognition.py", line 74, in <module>\r\n    face_client.person_group_person.add_face_from_stream(PERSON_GROUP_ID, janetceere.person_id,k)\r\n  File "C:\\Users\\Ceere\\AppData\\Local\\Programs\\Python\\Python39\\lib\\site-packages\\azure\\cognitiveservices\\vision\\face\\operations\\_person_group_person_operations.py", line 767, in add_face_from_stream\r\n    raise models.APIErrorException(self._deserialize, response)\r\nazure.cognitiveservices.vision.face.models._models_py3.APIErrorException: (InvalidImage) No face detected in the image.\r\n'
[I 220519 15:16:09 interface:184] b"Person group: a598810a-0ae0-446b-ad9d-cdb8ca6a428c\r\n[10, 3, 0, 11]\r\n[10, 3, 0, 11]\r\n[10, 3, 0, 11]\r\n[10, 3, 0, 11]\r\n\r\nTraining the person group...\r\nTraining status: succeeded.\r\n\r\nIdentifying faces in testimage.png\r\nPerson for face ID 4282e0b9-46ca-42f9-ac0c-3b6f7446e752 is identified in testimage.png with a confidence of 0.67136.\r\n'caminterface.py' is not recognized as an internal or external command,\r\r\noperable program or batch file.\r\r\n\r\n"
[I 220519 15:52:10 interface:184] b'Person group: 0075abd9-c9ba-4131-9542-c9bf81c72f6f\r\n[12, 13, 2, 10]\r\n[12, 13, 2, 10]\r\n[12, 13, 2, 10]\r\n[12, 13, 2, 10]\r\n\r\nTraining the person group...\r\nTraining status: succeeded.\r\n\r\nIdentifying faces in testimage.png\r\nPerson for face ID 15b1c1b2-c874-4837-83c2-a7b1237f817d is identified in testimage.png with a confidence of 0.64963.\r\nTraceback (most recent call last):\r\r\n  File "C:\\Users\\Ceere\\Documents\\computer Science\\fourth year docs\\project\\projectcodefinal\\cam.py", line 66, in <module>\r\r\n    out, err = sp.communicate()\r\r\nNameError: name \'sp\' is not defined\r\r\n\r\n'
[I 220519 15:55:01 interface:184] b'Person group: 1d02757f-8f2f-4f1b-9847-9850de1c0d2a\r\n[9, 14, 11, 2]\r\n[9, 14, 11, 2]\r\n'
[I 220519 15:55:01 interface:189] b'Traceback (most recent call last):\r\n  File "C:\\Users\\Ceere\\Documents\\computer Science\\fourth year docs\\project\\projectcodefinal\\facerecognition.py", line 74, in <module>\r\n    face_client.person_group_person.add_face_from_stream(PERSON_GROUP_ID, janetceere.person_id,k)\r\n  File "C:\\Users\\Ceere\\AppData\\Local\\Programs\\Python\\Python39\\lib\\site-packages\\azure\\cognitiveservices\\vision\\face\\operations\\_person_group_person_operations.py", line 767, in add_face_from_stream\r\n    raise models.APIErrorException(self._deserialize, response)\r\nazure.cognitiveservices.vision.face.models._models_py3.APIErrorException: (InvalidImage) No face detected in the image.\r\n'
[I 220519 15:57:21 interface:184] b'Person group: 5a12a05d-84bf-4377-8f28-d83e5b7e61ef\r\n[10, 8, 0, 3]\r\n[10, 8, 0, 3]\r\n[10, 8, 0, 3]\r\n[10, 8, 0, 3]\r\n\r\nTraining the person group...\r\nTraining status: running.\r\n\r\nTraining status: succeeded.\r\n\r\nIdentifying faces in testimage.png\r\nPerson for face ID 9ef9848e-14fa-4221-ad1b-5de9be631c26 is identified in testimage.png with a confidence of 0.63671.\r\nTraceback (most recent call last):\r\r\n  File "C:\\Users\\Ceere\\Documents\\computer Science\\fourth year docs\\project\\projectcodefinal\\cam.py", line 36, in <module>\r\r\n    out, err = sp.communicate()\r\r\nNameError: name \'sp\' is not defined\r\r\n[ WARN:0] global C:\\Users\\runneradmin\\AppData\\Local\\Temp\\pip-req-build-sn_xpupm\\opencv\\modules\\videoio\\src\\cap_msmf.cpp (438) `anonymous-namespace\'::SourceReaderCB::~SourceReaderCB terminating async callback\r\r\n\r\n'
[I 220519 16:01:31 interface:184] b'Person group: a16fe223-41ac-4592-913b-e2c75533af4d\r\n[0, 1, 13, 5]\r\n[0, 1, 13, 5]\r\n[0, 1, 13, 5]\r\n[0, 1, 13, 5]\r\n\r\nTraining the person group...\r\nTraining status: succeeded.\r\n\r\nIdentifying faces in testimage.png\r\nPerson for face ID c3bbce89-40cd-4a8d-9235-36811c3b8fdd is identified in testimage.png with a confidence of 0.66133.\r\nTraceback (most recent call last):\r\r\n  File "C:\\Users\\Ceere\\Documents\\computer Science\\fourth year docs\\project\\projectcodefinal\\cam.py", line 46, in <module>\r\r\n    out, err = sp.communicate()\r\r\nNameError: name \'sp\' is not defined\r\r\n[ WARN:0] global C:\\Users\\runneradmin\\AppData\\Local\\Temp\\pip-req-build-sn_xpupm\\opencv\\modules\\videoio\\src\\cap_msmf.cpp (438) `anonymous-namespace\'::SourceReaderCB::~SourceReaderCB terminating async callback\r\r\n\r\n'
[I 220519 16:04:52 interface:184] b'Person group: 29ee64d2-216b-4ab3-8ec0-b36f807253cf\r\n[1, 7, 5, 8]\r\n[1, 7, 5, 8]\r\n[1, 7, 5, 8]\r\n[1, 7, 5, 8]\r\n\r\nTraining the person group...\r\nTraining status: running.\r\n\r\nTraining status: succeeded.\r\n\r\nIdentifying faces in testimage.png\r\nPerson for face ID 920f261a-4309-4411-902f-545be79b9530 is identified in testimage.png with a confidence of 0.63858.\r\n[ WARN:0] global C:\\Users\\runneradmin\\AppData\\Local\\Temp\\pip-req-build-sn_xpupm\\opencv\\modules\\videoio\\src\\cap_msmf.cpp (438) `anonymous-namespace\'::SourceReaderCB::~SourceReaderCB terminating async callback\r\r\nTraceback (most recent call last):\r\r\n  File "C:\\Users\\Ceere\\Documents\\computer Science\\fourth year docs\\project\\projectcodefinal\\cam.py", line 33, in <module>\r\r\n    frame = cv2.resize(frameOrig, frameSize)\r\r\ncv2.error: OpenCV(4.5.3) C:\\Users\\runneradmin\\AppData\\Local\\Temp\\pip-req-build-sn_xpupm\\opencv\\modules\\imgproc\\src\\resize.cpp:4051: error: (-215:Assertion failed) !ssize.empty() in function \'cv::resize\'\r\r\n\r\r\n\r\n'
[I 220519 16:09:06 interface:184] b'Person group: dc8cf7fd-3b07-4dcb-8f8b-7b4a32019e89\r\n[14, 13, 10, 2]\r\n'
[I 220519 16:09:06 interface:189] b'Traceback (most recent call last):\r\n  File "C:\\Users\\Ceere\\Documents\\computer Science\\fourth year docs\\project\\projectcodefinal\\facerecognition.py", line 74, in <module>\r\n    face_client.person_group_person.add_face_from_stream(PERSON_GROUP_ID, janetceere.person_id,k)\r\n  File "C:\\Users\\Ceere\\AppData\\Local\\Programs\\Python\\Python39\\lib\\site-packages\\azure\\cognitiveservices\\vision\\face\\operations\\_person_group_person_operations.py", line 767, in add_face_from_stream\r\n    raise models.APIErrorException(self._deserialize, response)\r\nazure.cognitiveservices.vision.face.models._models_py3.APIErrorException: (InvalidImage) No face detected in the image.\r\n'
[I 220519 16:11:35 interface:184] b'Person group: e86eeddb-5f79-40fb-aaf9-d1a89d3a6d4a\r\n[4, 8, 9, 7]\r\n[4, 8, 9, 7]\r\n[4, 8, 9, 7]\r\n[4, 8, 9, 7]\r\n\r\nTraining the person group...\r\nTraining status: succeeded.\r\n\r\nIdentifying faces in testimage.png\r\nPerson for face ID b6260281-0952-49c9-90fd-e78d8ba91253 is identified in testimage.png with a confidence of 0.66185.\r\nTraceback (most recent call last):\r\r\n  File "C:\\Users\\Ceere\\Documents\\computer Science\\fourth year docs\\project\\projectcodefinal\\cam.py", line 35, in <module>\r\r\n    frame = cv2.resize(frame = cv2.resize(frame, None, fx=scaling_factor, fy=scaling_factor, interpolation=cv2.INTER_AREA))\r\r\nNameError: name \'frame\' is not defined\r\r\n[ WARN:0] global C:\\Users\\runneradmin\\AppData\\Local\\Temp\\pip-req-build-sn_xpupm\\opencv\\modules\\videoio\\src\\cap_msmf.cpp (438) `anonymous-namespace\'::SourceReaderCB::~SourceReaderCB terminating async callback\r\r\n\r\n'
[I 220519 16:46:38 interface:184] b'Person group: 3f42f735-dfde-456e-bd87-ab087a39d132\r\n[10, 0, 11, 3]\r\n[10, 0, 11, 3]\r\n[10, 0, 11, 3]\r\n[10, 0, 11, 3]\r\n\r\nTraining the person group...\r\nTraining status: succeeded.\r\n\r\nIdentifying faces in testimage.png\r\nPerson for face ID bd618966-4886-425e-aea6-86b2682718c5 is identified in testimage.png with a confidence of 0.63512.\r\nTraceback (most recent call last):\r\r\n  File "C:\\Users\\Ceere\\Documents\\computer Science\\fourth year docs\\project\\projectcodefinal\\cam.py", line 35, in <module>\r\r\n    frame = cv2.resize(frame = cv2.resize(frame, None, fx=scaling_factor, fy=scaling_factor, interpolation=cv2.INTER_AREA))\r\r\ncv2.error: OpenCV(4.5.3) :-1: error: (-5:Bad argument) in function \'resize\'\r\r\n> Overload resolution failed:\r\r\n>  - resize() missing required argument \'src\' (pos 1)\r\r\n>  - resize() missing required argument \'src\' (pos 1)\r\r\n\r\r\n[ WARN:0] global C:\\Users\\runneradmin\\AppData\\Local\\Temp\\pip-req-build-sn_xpupm\\opencv\\modules\\videoio\\src\\cap_msmf.cpp (438) `anonymous-namespace\'::SourceReaderCB::~SourceReaderCB terminating async callback\r\r\n\r\n'
[I 220519 16:50:52 interface:184] b'Person group: 7a1a9a79-3c48-49ae-b3a9-ef38389e24b4\r\n[5, 4, 11, 3]\r\n[5, 4, 11, 3]\r\n[5, 4, 11, 3]\r\n[5, 4, 11, 3]\r\n\r\nTraining the person group...\r\nTraining status: succeeded.\r\n\r\nIdentifying faces in testimage.png\r\nPerson for face ID 26fe8459-b8ef-4f06-9478-a35bdc1e74ab is identified in testimage.png with a confidence of 0.68347.\r\n[ WARN:0] global C:\\Users\\runneradmin\\AppData\\Local\\Temp\\pip-req-build-sn_xpupm\\opencv\\modules\\videoio\\src\\cap_msmf.cpp (438) `anonymous-namespace\'::SourceReaderCB::~SourceReaderCB terminating async callback\r\r\nTraceback (most recent call last):\r\r\n  File "C:\\Users\\Ceere\\Documents\\computer Science\\fourth year docs\\project\\projectcodefinal\\cam.py", line 32, in <module>\r\r\n    frame = cv2.resize(frame, None, fx=scaling_factor, fy=scaling_factor, interpolation=cv2.INTER_AREA)\r\r\ncv2.error: OpenCV(4.5.3) C:\\Users\\runneradmin\\AppData\\Local\\Temp\\pip-req-build-sn_xpupm\\opencv\\modules\\imgproc\\src\\resize.cpp:4051: error: (-215:Assertion failed) !ssize.empty() in function \'cv::resize\'\r\r\n\r\r\n\r\n'
[I 220519 16:56:49 interface:184] b"Person group: ace22469-f3ff-42e6-8081-65ef8f2ec8cc\r\n[0, 13, 8, 11]\r\n[0, 13, 8, 11]\r\n[0, 13, 8, 11]\r\n[0, 13, 8, 11]\r\n\r\nTraining the person group...\r\nTraining status: succeeded.\r\n\r\nIdentifying faces in testimage.png\r\nPerson for face ID f5d82d26-2193-4374-bae3-6585511277b5 is identified in testimage.png with a confidence of 0.63791.\r\n[ WARN:0] global C:\\Users\\runneradmin\\AppData\\Local\\Temp\\pip-req-build-sn_xpupm\\opencv\\modules\\videoio\\src\\cap_msmf.cpp (438) `anonymous-namespace'::SourceReaderCB::~SourceReaderCB terminating async callback\r\r\n\r\n"
[I 220519 23:39:31 interface:184] b"Person group: c7339285-475b-4bbd-8692-ba6af3e68cfb\r\n[6, 10, 3, 12]\r\n[6, 10, 3, 12]\r\n[6, 10, 3, 12]\r\n[6, 10, 3, 12]\r\n\r\nTraining the person group...\r\nTraining status: running.\r\n\r\nTraining status: succeeded.\r\n\r\nIdentifying faces in testimage.png\r\nPerson for face ID 14b07e95-f412-4b1a-b341-71caa869778a is identified in testimage.png with a confidence of 0.55223.\r\n[ WARN:0@37.904] global D:\\a\\opencv-python\\opencv-python\\opencv\\modules\\videoio\\src\\cap_msmf.cpp (539) `anonymous-namespace'::SourceReaderCB::~SourceReaderCB terminating async callback\r\r\n\r\n"
[I 220520 00:42:53 interface:184] b"Person group: 4f9e2a95-4c3d-4943-9213-6703783fda6b\r\n[7, 2, 9, 10]\r\n[7, 2, 9, 10]\r\n[7, 2, 9, 10]\r\n[7, 2, 9, 10]\r\n\r\nTraining the person group...\r\nTraining status: running.\r\n\r\nTraining status: succeeded.\r\n\r\nIdentifying faces in testimage.png\r\nPerson for face ID 7f041fe7-1334-4b2c-b692-a553493253ef is identified in testimage.png with a confidence of 0.59619.\r\n[ WARN:0@10.626] global D:\\a\\opencv-python\\opencv-python\\opencv\\modules\\videoio\\src\\cap_msmf.cpp (539) `anonymous-namespace'::SourceReaderCB::~SourceReaderCB terminating async callback\r\r\n\r\n"
[I 220520 01:15:42 interface:184] b'Person group: 47b7f34d-4861-4e42-abc4-842d0dddf741\r\n[12, 2, 13, 0]\r\n[12, 2, 13, 0]\r\n[12, 2, 13, 0]\r\n[12, 2, 13, 0]\r\n'
[I 220520 01:15:42 interface:189] b'Traceback (most recent call last):\r\n  File "C:\\Users\\Ceere\\Documents\\computer Science\\fourth year docs\\project\\projectcodefinal\\facerecognition.py", line 74, in <module>\r\n    face_client.person_group_person.add_face_from_stream(PERSON_GROUP_ID, janetceere.person_id,k)\r\n  File "C:\\Users\\Ceere\\AppData\\Local\\Programs\\Python\\Python39\\lib\\site-packages\\azure\\cognitiveservices\\vision\\face\\operations\\_person_group_person_operations.py", line 767, in add_face_from_stream\r\n    raise models.APIErrorException(self._deserialize, response)\r\nazure.cognitiveservices.vision.face.models._models_py3.APIErrorException: (InvalidImage) No face detected in the image.\r\n'
[I 220520 01:25:32 interface:184] b'Person group: 616e73e3-9332-436c-afb5-2469b7bef883\r\n[2, 6, 9, 8]\r\n[2, 6, 9, 8]\r\n[2, 6, 9, 8]\r\n[2, 6, 9, 8]\r\n\r\nTraining the person group...\r\nTraining status: succeeded.\r\n\r\nIdentifying faces in testimage.png\r\n'
[I 220520 09:19:20 interface:184] b'Person group: a21872f8-96e2-4d52-9bc2-7d593d31ef8d\r\n[13, 14, 0, 4]\r\n[13, 14, 0, 4]\r\n'
[I 220520 09:19:20 interface:189] b'Traceback (most recent call last):\r\n  File "C:\\Users\\Ceere\\Documents\\computer Science\\fourth year docs\\project\\projectcodefinal\\facerecognition.py", line 74, in <module>\r\n    face_client.person_group_person.add_face_from_stream(PERSON_GROUP_ID, janetceere.person_id,k)\r\n  File "C:\\Users\\Ceere\\AppData\\Local\\Programs\\Python\\Python39\\lib\\site-packages\\azure\\cognitiveservices\\vision\\face\\operations\\_person_group_person_operations.py", line 767, in add_face_from_stream\r\n    raise models.APIErrorException(self._deserialize, response)\r\nazure.cognitiveservices.vision.face.models._models_py3.APIErrorException: (InvalidImage) No face detected in the image.\r\n'
[I 220520 09:20:35 interface:184] b'Person group: ec5d9cf8-89e3-490a-8416-3eb5b086b2e3\r\n[6, 10, 14, 7]\r\n[6, 10, 14, 7]\r\n[6, 10, 14, 7]\r\n'
[I 220520 09:20:35 interface:189] b'Traceback (most recent call last):\r\n  File "C:\\Users\\Ceere\\Documents\\computer Science\\fourth year docs\\project\\projectcodefinal\\facerecognition.py", line 74, in <module>\r\n    face_client.person_group_person.add_face_from_stream(PERSON_GROUP_ID, janetceere.person_id,k)\r\n  File "C:\\Users\\Ceere\\AppData\\Local\\Programs\\Python\\Python39\\lib\\site-packages\\azure\\cognitiveservices\\vision\\face\\operations\\_person_group_person_operations.py", line 767, in add_face_from_stream\r\n    raise models.APIErrorException(self._deserialize, response)\r\nazure.cognitiveservices.vision.face.models._models_py3.APIErrorException: (InvalidImage) No face detected in the image.\r\n'
[I 220520 09:23:03 interface:184] b"Person group: 6e60c039-ad8f-4e72-a760-95816d84e054\r\n[3, 13, 0, 6]\r\n[3, 13, 0, 6]\r\n[3, 13, 0, 6]\r\n[3, 13, 0, 6]\r\n\r\nTraining the person group...\r\nTraining status: succeeded.\r\n\r\nIdentifying faces in testimage.png\r\nPerson for face ID 3db5dae0-b849-4eda-928b-83344989d36a is identified in testimage.png with a confidence of 0.6352.\r\n[ WARN:0@11.113] global D:\\a\\opencv-python\\opencv-python\\opencv\\modules\\videoio\\src\\cap_msmf.cpp (539) `anonymous-namespace'::SourceReaderCB::~SourceReaderCB terminating async callback\r\r\n\r\n"
[I 220520 09:27:06 interface:184] b"Person group: fc6ff032-5667-4d7f-9303-ef2c58e8c93b\r\n[5, 11, 3, 7]\r\n[5, 11, 3, 7]\r\n[5, 11, 3, 7]\r\n[5, 11, 3, 7]\r\n\r\nTraining the person group...\r\nTraining status: succeeded.\r\n\r\nIdentifying faces in testimage.png\r\nPerson for face ID 66c021f3-48c9-4c75-b885-325906584241 is identified in testimage.png with a confidence of 0.68019.\r\n[ WARN:0@5.754] global D:\\a\\opencv-python\\opencv-python\\opencv\\modules\\videoio\\src\\cap_msmf.cpp (539) `anonymous-namespace'::SourceReaderCB::~SourceReaderCB terminating async callback\r\r\n\r\n"
[I 220520 11:45:09 interface:184] b'Person group: 7a5ce4db-0157-47a2-9ad7-d43ce4098ce0\r\n[4, 14, 0, 10]\r\n[4, 14, 0, 10]\r\n'
[I 220520 11:45:09 interface:189] b'Traceback (most recent call last):\r\n  File "C:\\Users\\Ceere\\Documents\\computer Science\\fourth year docs\\project\\projectcodefinal\\facerecognition.py", line 74, in <module>\r\n    face_client.person_group_person.add_face_from_stream(PERSON_GROUP_ID, janetceere.person_id,k)\r\n  File "C:\\Users\\Ceere\\AppData\\Local\\Programs\\Python\\Python39\\lib\\site-packages\\azure\\cognitiveservices\\vision\\face\\operations\\_person_group_person_operations.py", line 767, in add_face_from_stream\r\n    raise models.APIErrorException(self._deserialize, response)\r\nazure.cognitiveservices.vision.face.models._models_py3.APIErrorException: (InvalidImage) No face detected in the image.\r\n'
[I 220520 11:48:16 interface:184] b'Person group: 0368a164-8cf3-4c1b-8139-df47cf90091b\r\n[7, 5, 6, 12]\r\n'
[I 220520 11:48:16 interface:189] b'Traceback (most recent call last):\r\n  File "C:\\Users\\Ceere\\Documents\\computer Science\\fourth year docs\\project\\projectcodefinal\\facerecognition.py", line 74, in <module>\r\n    face_client.person_group_person.add_face_from_stream(PERSON_GROUP_ID, janetceere.person_id,k)\r\n  File "C:\\Users\\Ceere\\AppData\\Local\\Programs\\Python\\Python39\\lib\\site-packages\\azure\\cognitiveservices\\vision\\face\\operations\\_person_group_person_operations.py", line 767, in add_face_from_stream\r\n    raise models.APIErrorException(self._deserialize, response)\r\nazure.cognitiveservices.vision.face.models._models_py3.APIErrorException: (InvalidImage) There is more than 1 face in the image.\r\n'
[I 220520 11:51:20 interface:184] b"Person group: 90f47f03-58fb-4fcb-ba8f-7e8494515ee2\r\n[3, 7, 9, 0]\r\n[3, 7, 9, 0]\r\n[3, 7, 9, 0]\r\n[3, 7, 9, 0]\r\n\r\nTraining the person group...\r\nTraining status: running.\r\n\r\nTraining status: succeeded.\r\n\r\nIdentifying faces in testimage.png\r\nPerson for face ID f2c16781-60b9-4edb-b90d-5c52f373b07e is identified in testimage.png with a confidence of 0.58682.\r\n[ WARN:0@21.003] global D:\\a\\opencv-python\\opencv-python\\opencv\\modules\\videoio\\src\\cap_msmf.cpp (539) `anonymous-namespace'::SourceReaderCB::~SourceReaderCB terminating async callback\r\r\n\r\n"
[I 220520 11:55:03 interface:184] b'Person group: 7b52b999-3546-446a-b4e1-2f04a645fd83\r\n[13, 9, 1, 7]\r\n[13, 9, 1, 7]\r\n[13, 9, 1, 7]\r\n[13, 9, 1, 7]\r\n\r\nTraining the person group...\r\nTraining status: running.\r\n\r\nTraining status: succeeded.\r\n\r\nIdentifying faces in testimage.png\r\nPerson for face ID 35bfbf5a-a9c1-443c-b255-e5af188afbe8 is identified in testimage.png with a confidence of 0.59614.\r\n'
[I 220520 12:14:05 interface:184] b'Person group: 3dddff1e-386b-4be6-b4c5-e2b234036cf3\r\n[9, 0, 5, 1]\r\n[9, 0, 5, 1]\r\n[9, 0, 5, 1]\r\n[9, 0, 5, 1]\r\n\r\nTraining the person group...\r\nTraining status: succeeded.\r\n\r\nIdentifying faces in testimage.png\r\n'
[I 220815 17:00:35 interface:184] b'Person group: 432ef5fd-128e-41d7-ad36-5d5d50a8f63f\r\n[11, 9, 12, 10]\r\n'
[I 220815 17:00:35 interface:189] b'Traceback (most recent call last):\r\n  File "C:\\Users\\Ceere\\Documents\\computer Science\\fourth year docs\\project\\projectcodefinal\\facerecognition.py", line 74, in <module>\r\n    face_client.person_group_person.add_face_from_stream(PERSON_GROUP_ID, janetceere.person_id,k)\r\n  File "C:\\Users\\Ceere\\AppData\\Local\\Programs\\Python\\Python39\\lib\\site-packages\\azure\\cognitiveservices\\vision\\face\\operations\\_person_group_person_operations.py", line 767, in add_face_from_stream\r\n    raise models.APIErrorException(self._deserialize, response)\r\nazure.cognitiveservices.vision.face.models._models_py3.APIErrorException: (InvalidImage) No face detected in the image.\r\n'
